<?xml version="1.0" ?>
<!-- =================================================================================== -->
<!-- |    This document was autogenerated by xacro from /home/aaryan/Desktop/rigbetel-labs-ws/src/scara_arm/scara_arm_description/urdf/scara_arm_two_finger_gripper.xacro | -->
<!-- |    EDITING THIS FILE BY HAND IS NOT RECOMMENDED                                 | -->
<!-- =================================================================================== -->
<robot name="scara_arm">
    <material name="silver">
        <color rgba="0.700 0.700 0.700 1.000" />
    </material>
    <transmission name="link_01_joint_tran">
        <type>transmission_interface/SimpleTransmission</type>
        <joint name="link_01_joint">
            <hardwareInterface>hardware_interface/PositionJointInterface</hardwareInterface>
        </joint>
        <actuator name="link_01_joint_actr">
            <hardwareInterface>hardware_interface/PositionJointInterface</hardwareInterface>
            <mechanicalReduction>1</mechanicalReduction>
        </actuator>
    </transmission>
    <transmission name="link_02_joint_tran">
        <type>transmission_interface/SimpleTransmission</type>
        <joint name="link_02_joint">
            <hardwareInterface>hardware_interface/PositionJointInterface</hardwareInterface>
        </joint>
        <actuator name="link_02_joint_actr">
            <hardwareInterface>hardware_interface/PositionJointInterface</hardwareInterface>
            <mechanicalReduction>1</mechanicalReduction>
        </actuator>
    </transmission>
    <transmission name="link_03_joint_tran">
        <type>transmission_interface/SimpleTransmission</type>
        <joint name="link_03_joint">
            <hardwareInterface>hardware_interface/PositionJointInterface</hardwareInterface>
        </joint>
        <actuator name="link_03_joint_actr">
            <hardwareInterface>hardware_interface/PositionJointInterface</hardwareInterface>
            <mechanicalReduction>1</mechanicalReduction>
        </actuator>
    </transmission>
    <transmission name="link_04_joint_tran">
        <type>transmission_interface/SimpleTransmission</type>
        <joint name="link_04_joint">
            <hardwareInterface>hardware_interface/PositionJointInterface</hardwareInterface>
        </joint>
        <actuator name="link_04_joint_actr">
            <hardwareInterface>hardware_interface/PositionJointInterface</hardwareInterface>
            <mechanicalReduction>1</mechanicalReduction>
        </actuator>
    </transmission>
    <gazebo>
        <plugin filename="libgazebo_ros_control.so" name="control" />
        <plugin name="gazebo_ros_control">
            <robotNamespace>/</robotNamespace>
        </plugin>
    </gazebo>
    <gazebo reference="base_link">
        <material>Gazebo/Silver</material>
        <mu1>0.2</mu1>
        <mu2>0.2</mu2>
        <selfCollide>true</selfCollide>
        <gravity>true</gravity>
    </gazebo>
    <gazebo reference="link_01_1">
        <material>Gazebo/Silver</material>
        <mu1>0.2</mu1>
        <mu2>0.2</mu2>
        <selfCollide>true</selfCollide>
    </gazebo>
    <gazebo reference="link_02_1">
        <material>Gazebo/Silver</material>
        <mu1>0.2</mu1>
        <mu2>0.2</mu2>
        <selfCollide>true</selfCollide>
    </gazebo>
    <gazebo reference="link_03_1">
        <material>Gazebo/Silver</material>
        <mu1>0.2</mu1>
        <mu2>0.2</mu2>
        <selfCollide>true</selfCollide>
    </gazebo>
    <gazebo reference="link_04_1">
        <material>Gazebo/Silver</material>
        <mu1>0.2</mu1>
        <mu2>0.2</mu2>
        <selfCollide>true</selfCollide>
    </gazebo>
    <link name="world" />
    <joint name="world_joint" type="fixed">
        <origin rpy="0 0 0" xyz="0 0 0.25" />
        <parent link="world" />
        <child link="base_link" />
    </joint>
    <link name="base_link">
        <inertial>
            <origin rpy="0 0 0" xyz="-0.11835854812758473 -0.000276888564792295 0.07546314461319549" />
            <mass value="9.76941358714018" />
            <inertia ixx="0.040462" ixy="0.000229" ixz="0.003341" iyy="0.058748" iyz="3e-06" izz="0.065063" />
        </inertial>
        <visual>
            <origin rpy="0 0 0" xyz="0 0 0" />
            <geometry>
                <mesh filename="package://scara_arm_description/meshes/base_link.stl" scale="0.001 0.001 0.001" />
            </geometry>
            <material name="silver" />
        </visual>
        <collision>
            <origin rpy="0 0 0" xyz="0 0 0" />
            <geometry>
                <mesh filename="package://scara_arm_description/meshes/base_link.stl" scale="0.001 0.001 0.001" />
            </geometry>
        </collision>
    </link>
    <link name="link_01_1">
        <inertial>
            <origin rpy="0 0 0" xyz="0.08670878750712241 1.200325802990558e-08 0.006656155794027313" />
            <mass value="1.9187641006386469" />
            <inertia ixx="0.001419" ixy="0.0" ixz="-0.000439" iyy="0.016505" iyz="0.0" izz="0.017605" />
        </inertial>
        <visual>
            <origin rpy="0 0 0" xyz="0.089 -0.0 -0.134" />
            <geometry>
                <mesh filename="package://scara_arm_description/meshes/link_01_1.stl" scale="0.001 0.001 0.001" />
            </geometry>
            <material name="silver" />
        </visual>
        <collision>
            <origin rpy="0 0 0" xyz="0.089 -0.0 -0.134" />
            <geometry>
                <mesh filename="package://scara_arm_description/meshes/link_01_1.stl" scale="0.001 0.001 0.001" />
            </geometry>
        </collision>
    </link>
    <link name="link_02_1">
        <inertial>
            <origin rpy="0 0 0" xyz="0.08442650829809627 -0.00019960790751640374 0.04670690112194936" />
            <mass value="4.429642089527778" />
            <inertia ixx="0.010022" ixy="0.000108" ixz="0.003844" iyy="0.037429" iyz="-1.5e-05" izz="0.034386" />
        </inertial>
        <visual>
            <origin rpy="0 0 0" xyz="-0.109 -0.0 -0.150161" />
            <geometry>
                <mesh filename="package://scara_arm_description/meshes/link_02_1.stl" scale="0.001 0.001 0.001" />
            </geometry>
            <material name="silver" />
        </visual>
        <collision>
            <origin rpy="0 0 0" xyz="-0.109 -0.0 -0.150161" />
            <geometry>
                <mesh filename="package://scara_arm_description/meshes/link_02_1.stl" scale="0.001 0.001 0.001" />
            </geometry>
        </collision>
    </link>
    <link name="link_03_1">
        <inertial>
            <origin rpy="0 0 0" xyz="7.948171955463046e-05 0.015947235193624242 0.007476972757145983" />
            <mass value="1.573240852398478" />
            <inertia ixx="0.031125" ixy="-1e-06" ixz="0.000175" iyy="0.031053" iyz="0.000143" izz="0.000561" />
        </inertial>
        <visual>
            <origin rpy="0 0 0" xyz="-0.321 0.014923 -0.190844" />
            <geometry>
                <mesh filename="package://scara_arm_description/meshes/link_03_1.stl" scale="0.001 0.001 0.001" />
            </geometry>
            <material name="silver" />
        </visual>
        <collision>
            <origin rpy="0 0 0" xyz="-0.321 0.014923 -0.190844" />
            <geometry>
                <mesh filename="package://scara_arm_description/meshes/link_03_1.stl" scale="0.001 0.001 0.001" />
            </geometry>
        </collision>
    </link>
    <link name="link_04_1">
        <inertial>
            <origin rpy="0 0 0" xyz="-6.87288058324742e-05 -3.7241785767553145e-11 -0.004999674402307544" />
            <mass value="0.1300483969226679" />
            <inertia ixx="1.8e-05" ixy="0.0" ixz="0.0" iyy="1.8e-05" iyz="0.0" izz="3.4e-05" />
        </inertial>
        <visual>
            <origin rpy="0 0 0" xyz="-0.3217 0.0 -0.087161" />
            <geometry>
                <mesh filename="package://scara_arm_description/meshes/link_04_1.stl" scale="0.001 0.001 0.001" />
            </geometry>
            <material name="silver" />
        </visual>
        <collision>
            <origin rpy="0 0 0" xyz="-0.3217 0.0 -0.087161" />
            <geometry>
                <mesh filename="package://scara_arm_description/meshes/link_04_1.stl" scale="0.001 0.001 0.001" />
            </geometry>
        </collision>
    </link>
    <joint name="link_01_joint" type="revolute">
        <origin rpy="0 0 0" xyz="-0.089 0.0 0.134" />
        <parent link="base_link" />
        <child link="link_01_1" />
        <axis xyz="0.0 -0.0 1.0" />
        <limit effort="100" lower="-1.43117" upper="1.71042" velocity="100" />
    </joint>
    <joint name="link_02_joint" type="revolute">
        <origin rpy="0 0 0" xyz="0.198 0.0 0.016161" />
        <parent link="link_01_1" />
        <child link="link_02_1" />
        <axis xyz="0.0 0.0 1.0" />
        <limit effort="100" lower="-1.71042" upper="1.43117" velocity="100" />
    </joint>
    <joint name="link_03_joint" type="prismatic">
        <origin rpy="0 0 0" xyz="0.212 -0.014923 0.040683" />
        <parent link="link_02_1" />
        <child link="link_03_1" />
        <axis xyz="0.0 0.0 1.0" />
        <limit effort="100" lower="-0.23" upper="0.0" velocity="100" />
    </joint>
    <joint name="link_04_joint" type="revolute">
        <origin rpy="0 0 0" xyz="0.0007 0.014923 -0.103683" />
        <parent link="link_03_1" />
        <child link="link_04_1" />
        <axis xyz="0.0 0.0 -1.0" />
        <limit effort="100" lower="-1.570796" upper="1.570796" velocity="100" />
    </joint>
    <transmission name="gripper_joint_tran">
        <type>transmission_interface/SimpleTransmission</type>
        <joint name="gripper_joint">
            <hardwareInterface>hardware_interface/EffortJointInterface</hardwareInterface>
        </joint>
        <actuator name="gripper_joint_actr">
            <hardwareInterface>hardware_interface/EffortJointInterface</hardwareInterface>
            <mechanicalReduction>1</mechanicalReduction>
        </actuator>
    </transmission>
    <transmission name="right_gripper_joint_tran">
        <type>transmission_interface/SimpleTransmission</type>
        <joint name="right_gripper_joint">
            <hardwareInterface>hardware_interface/EffortJointInterface</hardwareInterface>
        </joint>
        <actuator name="right_gripper_joint_actr">
            <hardwareInterface>hardware_interface/EffortJointInterface</hardwareInterface>
            <mechanicalReduction>1</mechanicalReduction>
        </actuator>
    </transmission>
    <transmission name="left_gripper_joint_tran">
        <type>transmission_interface/SimpleTransmission</type>
        <joint name="left_gripper_joint">
            <hardwareInterface>hardware_interface/EffortJointInterface</hardwareInterface>
        </joint>
        <actuator name="left_gripper_joint_actr">
            <hardwareInterface>hardware_interface/EffortJointInterface</hardwareInterface>
            <mechanicalReduction>1</mechanicalReduction>
        </actuator>
    </transmission>
    <gazebo>
        <plugin filename="libgazebo_ros_control.so" name="control" />
    </gazebo>
    <gazebo reference="gripper_base_link">
        <material>Gazebo/Silver</material>
        <mu1>0.2</mu1>
        <mu2>0.2</mu2>
        <selfCollide>true</selfCollide>
        <gravity>true</gravity>
    </gazebo>
    <gazebo reference="pinion_1">
        <material>Gazebo/Silver</material>
        <mu1>0.2</mu1>
        <mu2>0.2</mu2>
        <selfCollide>true</selfCollide>
    </gazebo>
    <gazebo reference="gripper_right_1">
        <material>Gazebo/Silver</material>
        <mu1>0.2</mu1>
        <mu2>0.2</mu2>
        <selfCollide>true</selfCollide>
    </gazebo>
    <gazebo reference="gripper_left_1">
        <material>Gazebo/Silver</material>
        <mu1>0.2</mu1>
        <mu2>0.2</mu2>
        <selfCollide>true</selfCollide>
    </gazebo>
    <link name="gripper_base_link">
        <inertial>
            <origin rpy="0 0 0" xyz="0.023843975149766813 -0.007551602066560885 -1.7803166319307262e-07" />
            <mass value="0.7371676511848216" />
            <inertia ixx="0.000313" ixy="-1.3e-05" ixz="0.0" iyy="0.000272" iyz="0.0" izz="0.000299" />
        </inertial>
        <visual>
            <origin rpy="0 0 0" xyz="0 0 0" />
            <geometry>
                <mesh filename="package://two_finger_gripper_description/meshes/gripper_base_link.stl" scale="0.001 0.001 0.001" />
            </geometry>
            <material name="silver" />
        </visual>
        <collision>
            <origin rpy="0 0 0" xyz="0 0 0" />
            <geometry>
                <mesh filename="package://two_finger_gripper_description/meshes/gripper_base_link.stl" scale="0.001 0.001 0.001" />
            </geometry>
        </collision>
    </link>
    <link name="pinion_1">
        <inertial>
            <origin rpy="0 0 0" xyz="0.0034043394457755963 1.3778876043618604e-12 -1.2631614722542942e-12" />
            <mass value="0.020624177027043226" />
            <inertia ixx="2e-06" ixy="-0.0" ixz="0.0" iyy="1e-06" iyz="-0.0" izz="1e-06" />
        </inertial>
        <visual>
            <origin rpy="0 0 0" xyz="-0.0485 -0.001 0.0" />
            <geometry>
                <mesh filename="package://two_finger_gripper_description/meshes/pinion_1.stl" scale="0.001 0.001 0.001" />
            </geometry>
            <material name="silver" />
        </visual>
        <collision>
            <origin rpy="0 0 0" xyz="-0.0485 -0.001 0.0" />
            <geometry>
                <mesh filename="package://two_finger_gripper_description/meshes/pinion_1.stl" scale="0.001 0.001 0.001" />
            </geometry>
        </collision>
    </link>
    <link name="gripper_right_1">
        <inertial>
            <origin rpy="0 0 0" xyz="0.010859809536370418 -0.0037061649756109875 -0.016631094134670964" />
            <mass value="0.19983948074258262" />
            <inertia ixx="6.3e-05" ixy="6e-06" ixz="7e-06" iyy="5.4e-05" iyz="8e-06" izz="6.8e-05" />
        </inertial>
        <visual>
            <origin rpy="0 0 0" xyz="-0.0567 -0.014 -0.0182" />
            <geometry>
                <mesh filename="package://two_finger_gripper_description/meshes/gripper_right_1.stl" scale="0.001 0.001 0.001" />
            </geometry>
            <material name="silver" />
        </visual>
        <collision>
            <origin rpy="0 0 0" xyz="-0.0567 -0.014 -0.0182" />
            <geometry>
                <mesh filename="package://two_finger_gripper_description/meshes/gripper_right_1.stl" scale="0.001 0.001 0.001" />
            </geometry>
        </collision>
    </link>
    <link name="gripper_left_1">
        <inertial>
            <origin rpy="0 0 0" xyz="0.010257810630306105 0.003203941855784714 0.016553712338734785" />
            <mass value="0.18914730605530125" />
            <inertia ixx="6.1e-05" ixy="-4e-06" ixz="-6e-06" iyy="5.1e-05" iyz="8e-06" izz="6.6e-05" />
        </inertial>
        <visual>
            <origin rpy="0 0 0" xyz="-0.0567 0.012 0.0182" />
            <geometry>
                <mesh filename="package://two_finger_gripper_description/meshes/gripper_left_1.stl" scale="0.001 0.001 0.001" />
            </geometry>
            <material name="silver" />
        </visual>
        <collision>
            <origin rpy="0 0 0" xyz="-0.0567 0.012 0.0182" />
            <geometry>
                <mesh filename="package://two_finger_gripper_description/meshes/gripper_left_1.stl" scale="0.001 0.001 0.001" />
            </geometry>
        </collision>
    </link>
    <joint name="gripper_joint" type="revolute">
        <origin rpy="0 0 0" xyz="0.0485 0.001 0.0" />
        <parent link="gripper_base_link" />
        <child link="pinion_1" />
        <axis xyz="1.0 -0.0 -0.0" />
        <limit effort="100" lower="0.0" upper="3.141593" velocity="100" />
    </joint>
    <joint name="right_gripper_joint" type="prismatic">
        <origin rpy="0 0 0" xyz="0.0567 0.014 0.0182" />
        <parent link="gripper_base_link" />
        <child link="gripper_right_1" />
        <axis xyz="0.0 1.0 0.0" />
        <limit effort="100" lower="0.001" upper="0.035" velocity="100" />
    </joint>
    <joint name="left_gripper_joint" type="prismatic">
        <origin rpy="0 0 0" xyz="0.0567 -0.012 -0.0182" />
        <parent link="gripper_base_link" />
        <child link="gripper_left_1" />
        <axis xyz="0.0 1.0 0.0" />
        <limit effort="100" lower="-0.035" upper="-0.001" velocity="100" />
    </joint>
    <joint name="gripper_attach" type="fixed">
        <origin rpy="0 1.5708 0" xyz="0 0 0" />
        <parent link="link_04_1" />
        <child link="gripper_base_link" />
    </joint>
</robot>
