<?xml version="1.0" ?>
<robot name="vacuum_gripper" xmlns:xacro="http://www.ros.org/wiki/xacro">

<!-- <xacro:include filename="$(find vacuum_gripper_description)/urdf/materials.xacro" /> -->
<xacro:include filename="$(find vacuum_gripper_description)/urdf/vacuum_gripper.trans" />
<xacro:include filename="$(find vacuum_gripper_description)/urdf/vacuum_gripper.gazebo" />
<link name="gripper_base_link">
  <inertial>
    <origin xyz="0.012152318878142441 0.00989984571459361 -0.05720243618145755" rpy="0 0 0"/>
    <mass value="0.8034775156193473"/>
    <inertia ixx="0.000793" iyy="0.000806" izz="0.000631" ixy="9.2e-05" iyz="9e-05" ixz="-6.1e-05"/>
  </inertial>
  <visual>
    <origin xyz="0 0 0" rpy="0 0 0"/>
    <geometry>
      <mesh filename="package://vacuum_gripper_description/meshes/gripper_base_link.stl" scale="0.001 0.001 0.001"/>
    </geometry>
    <material name="silver"/>
  </visual>
  <collision>
    <origin xyz="0 0 0" rpy="0 0 0"/>
    <geometry>
      <mesh filename="package://vacuum_gripper_description/meshes/gripper_base_link.stl" scale="0.001 0.001 0.001"/>
    </geometry>
  </collision>
</link>

<link name="gripper_link_1">
  <inertial>
    <origin xyz="2.943394468511826e-07 2.2149824879902726e-07 -0.0024999999999999675" rpy="0 0 0"/>
    <mass value="0.002457048975733048"/>
    <inertia ixx="0.0" iyy="0.0" izz="0.0" ixy="-0.0" iyz="0.0" ixz="0.0"/>
  </inertial>
  <visual>
    <origin xyz="-0.000371 -2.9e-05 0.0505" rpy="0 0 0"/>
    <geometry>
      <mesh filename="package://vacuum_gripper_description/meshes/gripper_link_1.stl" scale="0.001 0.001 0.001"/>
    </geometry>
    <material name="silver"/>
  </visual>
  <collision>
    <origin xyz="-0.000371 -2.9e-05 0.0505" rpy="0 0 0"/>
    <geometry>
      <mesh filename="package://vacuum_gripper_description/meshes/gripper_link_1.stl" scale="0.001 0.001 0.001"/>
    </geometry>
  </collision>
</link>

<joint name="gripper_joint" type="prismatic">
  <origin xyz="0.000371 2.9e-05 -0.0505" rpy="0 0 0"/>
  <parent link="gripper_base_link"/>
  <child link="gripper_link_1"/>
  <axis xyz="-0.0 -0.0 -1.0"/>
  <limit upper="0.02" lower="0.0" effort="100" velocity="100"/>
</joint>

</robot>
